[2019-03-22 13:26:41 -0400] [15179] [INFO] Starting gunicorn 19.9.0
[2019-03-22 13:26:41 -0400] [15179] [INFO] Listening at: http://127.0.0.1:8000 (15179)
[2019-03-22 13:26:41 -0400] [15179] [INFO] Using worker: sync
[2019-03-22 13:26:41 -0400] [15182] [INFO] Booting worker with pid: 15182
INFO     
ctxdoing
============================
v1.0.0 beta released on 19-Dec-2018
============================
OS: Linux-4.15.0-46-generic-x86_64-with-Ubuntu-18.04-bionic
Python: 3.6.7 (default, Oct 22 2018, 11:32:17) 
[GCC 8.2.0]
System: omkar on ddasuptools/10.207.84.149
Working directory: /home/omkar/git/ctxdoing/backend
Commandline: /home/omkar/git/ctxdoing/backend/ve/bin/gunicorn wsgi
============================
Log file: /home/omkar/git/ctxdoing/backend/ctxdoing.log
============================
    
INFO     Reset uploaded ASUP files
INFO     [asup_file_input_method=FILE_UPLOAD] ASUP file saved locally as: /home/omkar/git/ctxdoing/backend/autosupport.4
INFO     Selected ASUP files for analysis: [{'filePath': 'autosupport.4', 'generatedDate': 'Mon Jan 28 2019 06:24:43'}]
WARNING  The name of the autosupport file for calculating lrepl_client_time_stats:b'autosupport.4'
WARNING  The name of the autosupport file for calculating lrepl_client_time_stats:b'autosupport.4'
ERROR    Exception on /api/asup/analysis/replication_contexts/time_spent [GET]
Traceback (most recent call last):
  File "/home/omkar/git/ctxdoing/backend/ve/lib/python3.6/site-packages/flask/app.py", line 2292, in wsgi_app
    response = self.full_dispatch_request()
  File "/home/omkar/git/ctxdoing/backend/ve/lib/python3.6/site-packages/flask/app.py", line 1815, in full_dispatch_request
    rv = self.handle_user_exception(e)
  File "/home/omkar/git/ctxdoing/backend/ve/lib/python3.6/site-packages/flask_cors/extension.py", line 161, in wrapped_function
    return cors_after_request(app.make_response(f(*args, **kwargs)))
  File "/home/omkar/git/ctxdoing/backend/ve/lib/python3.6/site-packages/flask/app.py", line 1718, in handle_user_exception
    reraise(exc_type, exc_value, tb)
  File "/home/omkar/git/ctxdoing/backend/ve/lib/python3.6/site-packages/flask/_compat.py", line 35, in reraise
    raise value
  File "/home/omkar/git/ctxdoing/backend/ve/lib/python3.6/site-packages/flask/app.py", line 1813, in full_dispatch_request
    rv = self.dispatch_request()
  File "/home/omkar/git/ctxdoing/backend/ve/lib/python3.6/site-packages/flask/app.py", line 1799, in dispatch_request
    return self.view_functions[rule.endpoint](**req.view_args)
  File "/home/omkar/git/ctxdoing/backend/rest_api_server/asup_analysis_apis.py", line 241, in analyze_replication_contexts
    final_data_structure=dd.get_replication_analysis(selected_replication_contexts,app)
  File "/home/omkar/git/ctxdoing/backend/rest_api_server/dellemc/datadomain.py", line 758, in get_replication_analysis
    returned_graph=graph.plot_context(list_ctx_usage_time,os.path.join(save_name_path,save_name))
  File "/home/omkar/git/ctxdoing/backend/rest_api_server/dellemc/replicationcontextplot.py", line 86, in plot_context
    fig1, ax1 = plt.subplots()
  File "/home/omkar/git/ctxdoing/backend/ve/lib/python3.6/site-packages/matplotlib/pyplot.py", line 1217, in subplots
    fig = figure(**fig_kw)
  File "/home/omkar/git/ctxdoing/backend/ve/lib/python3.6/site-packages/matplotlib/pyplot.py", line 525, in figure
    **kwargs)
  File "/home/omkar/git/ctxdoing/backend/ve/lib/python3.6/site-packages/matplotlib/backend_bases.py", line 3218, in new_figure_manager
    return cls.new_figure_manager_given_figure(num, fig)
  File "/home/omkar/git/ctxdoing/backend/ve/lib/python3.6/site-packages/matplotlib/backends/_backend_tk.py", line 1008, in new_figure_manager_given_figure
    window = Tk.Tk(className="matplotlib")
  File "/usr/lib/python3.6/tkinter/__init__.py", line 2023, in __init__
    self.tk = _tkinter.create(screenName, baseName, className, interactive, wantobjects, useTk, sync, use)
_tkinter.TclError: couldn't connect to display "localhost:10.0"
WARNING  The name of the autosupport file for calculating lrepl_client_time_stats:b'autosupport.4'
WARNING  The name of the autosupport file for calculating lrepl_client_time_stats:b'autosupport.4'
ERROR    Exception on /api/asup/analysis/replication_contexts/time_spent [GET]
Traceback (most recent call last):
  File "/home/omkar/git/ctxdoing/backend/ve/lib/python3.6/site-packages/flask/app.py", line 2292, in wsgi_app
    response = self.full_dispatch_request()
  File "/home/omkar/git/ctxdoing/backend/ve/lib/python3.6/site-packages/flask/app.py", line 1815, in full_dispatch_request
    rv = self.handle_user_exception(e)
  File "/home/omkar/git/ctxdoing/backend/ve/lib/python3.6/site-packages/flask_cors/extension.py", line 161, in wrapped_function
    return cors_after_request(app.make_response(f(*args, **kwargs)))
  File "/home/omkar/git/ctxdoing/backend/ve/lib/python3.6/site-packages/flask/app.py", line 1718, in handle_user_exception
    reraise(exc_type, exc_value, tb)
  File "/home/omkar/git/ctxdoing/backend/ve/lib/python3.6/site-packages/flask/_compat.py", line 35, in reraise
    raise value
  File "/home/omkar/git/ctxdoing/backend/ve/lib/python3.6/site-packages/flask/app.py", line 1813, in full_dispatch_request
    rv = self.dispatch_request()
  File "/home/omkar/git/ctxdoing/backend/ve/lib/python3.6/site-packages/flask/app.py", line 1799, in dispatch_request
    return self.view_functions[rule.endpoint](**req.view_args)
  File "/home/omkar/git/ctxdoing/backend/rest_api_server/asup_analysis_apis.py", line 241, in analyze_replication_contexts
    final_data_structure=dd.get_replication_analysis(selected_replication_contexts,app)
  File "/home/omkar/git/ctxdoing/backend/rest_api_server/dellemc/datadomain.py", line 758, in get_replication_analysis
    returned_graph=graph.plot_context(list_ctx_usage_time,os.path.join(save_name_path,save_name))
  File "/home/omkar/git/ctxdoing/backend/rest_api_server/dellemc/replicationcontextplot.py", line 86, in plot_context
    fig1, ax1 = plt.subplots()
  File "/home/omkar/git/ctxdoing/backend/ve/lib/python3.6/site-packages/matplotlib/pyplot.py", line 1217, in subplots
    fig = figure(**fig_kw)
  File "/home/omkar/git/ctxdoing/backend/ve/lib/python3.6/site-packages/matplotlib/pyplot.py", line 525, in figure
    **kwargs)
  File "/home/omkar/git/ctxdoing/backend/ve/lib/python3.6/site-packages/matplotlib/backend_bases.py", line 3218, in new_figure_manager
    return cls.new_figure_manager_given_figure(num, fig)
  File "/home/omkar/git/ctxdoing/backend/ve/lib/python3.6/site-packages/matplotlib/backends/_backend_tk.py", line 1008, in new_figure_manager_given_figure
    window = Tk.Tk(className="matplotlib")
  File "/usr/lib/python3.6/tkinter/__init__.py", line 2023, in __init__
    self.tk = _tkinter.create(screenName, baseName, className, interactive, wantobjects, useTk, sync, use)
_tkinter.TclError: couldn't connect to display "localhost:10.0"
INFO     Reset uploaded ASUP files
INFO     [asup_file_input_method=FILE_UPLOAD] ASUP file saved locally as: /home/omkar/git/ctxdoing/backend/autosupport
INFO     Selected ASUP files for analysis: [{'filePath': 'autosupport', 'generatedDate': 'Tue Jan 22 2019 06:00:34'}]
WARNING  The name of the autosupport file for calculating lrepl_client_time_stats:b'autosupport'
WARNING  The name of the autosupport file for calculating lrepl_client_time_stats:b'autosupport'
ERROR    Exception on /api/asup/analysis/replication_contexts/time_spent [GET]
Traceback (most recent call last):
  File "/home/omkar/git/ctxdoing/backend/ve/lib/python3.6/site-packages/flask/app.py", line 2292, in wsgi_app
    response = self.full_dispatch_request()
  File "/home/omkar/git/ctxdoing/backend/ve/lib/python3.6/site-packages/flask/app.py", line 1815, in full_dispatch_request
    rv = self.handle_user_exception(e)
  File "/home/omkar/git/ctxdoing/backend/ve/lib/python3.6/site-packages/flask_cors/extension.py", line 161, in wrapped_function
    return cors_after_request(app.make_response(f(*args, **kwargs)))
  File "/home/omkar/git/ctxdoing/backend/ve/lib/python3.6/site-packages/flask/app.py", line 1718, in handle_user_exception
    reraise(exc_type, exc_value, tb)
  File "/home/omkar/git/ctxdoing/backend/ve/lib/python3.6/site-packages/flask/_compat.py", line 35, in reraise
    raise value
  File "/home/omkar/git/ctxdoing/backend/ve/lib/python3.6/site-packages/flask/app.py", line 1813, in full_dispatch_request
    rv = self.dispatch_request()
  File "/home/omkar/git/ctxdoing/backend/ve/lib/python3.6/site-packages/flask/app.py", line 1799, in dispatch_request
    return self.view_functions[rule.endpoint](**req.view_args)
  File "/home/omkar/git/ctxdoing/backend/rest_api_server/asup_analysis_apis.py", line 241, in analyze_replication_contexts
    final_data_structure=dd.get_replication_analysis(selected_replication_contexts,app)
  File "/home/omkar/git/ctxdoing/backend/rest_api_server/dellemc/datadomain.py", line 758, in get_replication_analysis
    returned_graph=graph.plot_context(list_ctx_usage_time,os.path.join(save_name_path,save_name))
  File "/home/omkar/git/ctxdoing/backend/rest_api_server/dellemc/replicationcontextplot.py", line 86, in plot_context
    fig1, ax1 = plt.subplots()
  File "/home/omkar/git/ctxdoing/backend/ve/lib/python3.6/site-packages/matplotlib/pyplot.py", line 1217, in subplots
    fig = figure(**fig_kw)
  File "/home/omkar/git/ctxdoing/backend/ve/lib/python3.6/site-packages/matplotlib/pyplot.py", line 525, in figure
    **kwargs)
  File "/home/omkar/git/ctxdoing/backend/ve/lib/python3.6/site-packages/matplotlib/backend_bases.py", line 3218, in new_figure_manager
    return cls.new_figure_manager_given_figure(num, fig)
  File "/home/omkar/git/ctxdoing/backend/ve/lib/python3.6/site-packages/matplotlib/backends/_backend_tk.py", line 1008, in new_figure_manager_given_figure
    window = Tk.Tk(className="matplotlib")
  File "/usr/lib/python3.6/tkinter/__init__.py", line 2023, in __init__
    self.tk = _tkinter.create(screenName, baseName, className, interactive, wantobjects, useTk, sync, use)
_tkinter.TclError: couldn't connect to display "localhost:10.0"
INFO     Reset uploaded ASUP files
INFO     [asup_file_input_method=FILE_UPLOAD] ASUP file saved locally as: /home/omkar/git/ctxdoing/backend/autosupport
INFO     Reset uploaded ASUP files
INFO     [asup_file_input_method=FILE_UPLOAD] ASUP file saved locally as: /home/omkar/git/ctxdoing/backend/autosupport
INFO     Reset uploaded ASUP files
INFO     [asup_file_input_method=FILE_UPLOAD] ASUP file saved locally as: /home/omkar/git/ctxdoing/backend/autosupport
INFO     Selected ASUP files for analysis: [{'filePath': 'autosupport', 'generatedDate': 'Tue Jan 22 2019 06:00:34'}]
WARNING  The name of the autosupport file for calculating lrepl_client_time_stats:b'autosupport'
WARNING  The name of the autosupport file for calculating lrepl_client_time_stats:b'autosupport'
ERROR    Exception on /api/asup/analysis/replication_contexts/time_spent [GET]
Traceback (most recent call last):
  File "/home/omkar/git/ctxdoing/backend/ve/lib/python3.6/site-packages/flask/app.py", line 2292, in wsgi_app
    response = self.full_dispatch_request()
  File "/home/omkar/git/ctxdoing/backend/ve/lib/python3.6/site-packages/flask/app.py", line 1815, in full_dispatch_request
    rv = self.handle_user_exception(e)
  File "/home/omkar/git/ctxdoing/backend/ve/lib/python3.6/site-packages/flask_cors/extension.py", line 161, in wrapped_function
    return cors_after_request(app.make_response(f(*args, **kwargs)))
  File "/home/omkar/git/ctxdoing/backend/ve/lib/python3.6/site-packages/flask/app.py", line 1718, in handle_user_exception
    reraise(exc_type, exc_value, tb)
  File "/home/omkar/git/ctxdoing/backend/ve/lib/python3.6/site-packages/flask/_compat.py", line 35, in reraise
    raise value
  File "/home/omkar/git/ctxdoing/backend/ve/lib/python3.6/site-packages/flask/app.py", line 1813, in full_dispatch_request
    rv = self.dispatch_request()
  File "/home/omkar/git/ctxdoing/backend/ve/lib/python3.6/site-packages/flask/app.py", line 1799, in dispatch_request
    return self.view_functions[rule.endpoint](**req.view_args)
  File "/home/omkar/git/ctxdoing/backend/rest_api_server/asup_analysis_apis.py", line 241, in analyze_replication_contexts
    final_data_structure=dd.get_replication_analysis(selected_replication_contexts,app)
  File "/home/omkar/git/ctxdoing/backend/rest_api_server/dellemc/datadomain.py", line 758, in get_replication_analysis
    returned_graph=graph.plot_context(list_ctx_usage_time,os.path.join(save_name_path,save_name))
  File "/home/omkar/git/ctxdoing/backend/rest_api_server/dellemc/replicationcontextplot.py", line 86, in plot_context
    fig1, ax1 = plt.subplots()
  File "/home/omkar/git/ctxdoing/backend/ve/lib/python3.6/site-packages/matplotlib/pyplot.py", line 1217, in subplots
    fig = figure(**fig_kw)
  File "/home/omkar/git/ctxdoing/backend/ve/lib/python3.6/site-packages/matplotlib/pyplot.py", line 525, in figure
    **kwargs)
  File "/home/omkar/git/ctxdoing/backend/ve/lib/python3.6/site-packages/matplotlib/backend_bases.py", line 3218, in new_figure_manager
    return cls.new_figure_manager_given_figure(num, fig)
  File "/home/omkar/git/ctxdoing/backend/ve/lib/python3.6/site-packages/matplotlib/backends/_backend_tk.py", line 1008, in new_figure_manager_given_figure
    window = Tk.Tk(className="matplotlib")
  File "/usr/lib/python3.6/tkinter/__init__.py", line 2023, in __init__
    self.tk = _tkinter.create(screenName, baseName, className, interactive, wantobjects, useTk, sync, use)
_tkinter.TclError: couldn't connect to display "localhost:10.0"
INFO     Reset uploaded ASUP files
INFO     [asup_file_input_method=FILE_UPLOAD] ASUP file saved locally as: /home/omkar/git/ctxdoing/backend/autosupport
INFO     Reset uploaded ASUP files
INFO     [asup_file_input_method=FILE_UPLOAD] ASUP file saved locally as: /home/omkar/git/ctxdoing/backend/autosupport
INFO     Reset uploaded ASUP files
INFO     [asup_file_input_method=FILE_UPLOAD] ASUP file saved locally as: /home/omkar/git/ctxdoing/backend/autosupport
INFO     Reset uploaded ASUP files
INFO     [asup_file_input_method=FILE_UPLOAD] ASUP file saved locally as: /home/omkar/git/ctxdoing/backend/autosupport
INFO     Selected ASUP files for analysis: [{'filePath': 'autosupport', 'generatedDate': 'Fri Feb 8 2019 06:31:55'}]
WARNING  The name of the autosupport file for calculating lrepl_client_time_stats:b'autosupport'
INFO     REST API returns version: {'version': 'ctxdoing v1.0.0 beta released on 19-Dec-2018'}
INFO     Reset uploaded ASUP files
INFO     [asup_file_input_method=FILE_UPLOAD] ASUP file saved locally as: /home/omkar/git/ctxdoing/backend/autosupportturco
INFO     Selected ASUP files for analysis: [{'filePath': 'autosupportturco', 'generatedDate': 'Thu Feb 14 2019 06:12:51'}]
WARNING  The name of the autosupport file for calculating lrepl_client_time_stats:b'autosupportturco'
WARNING  The name of the autosupport file for calculating lrepl_client_time_stats:b'autosupportturco'
ERROR    Exception on /api/asup/analysis/replication_contexts/time_spent [GET]
Traceback (most recent call last):
  File "/home/omkar/git/ctxdoing/backend/ve/lib/python3.6/site-packages/flask/app.py", line 2292, in wsgi_app
    response = self.full_dispatch_request()
  File "/home/omkar/git/ctxdoing/backend/ve/lib/python3.6/site-packages/flask/app.py", line 1815, in full_dispatch_request
    rv = self.handle_user_exception(e)
  File "/home/omkar/git/ctxdoing/backend/ve/lib/python3.6/site-packages/flask_cors/extension.py", line 161, in wrapped_function
    return cors_after_request(app.make_response(f(*args, **kwargs)))
  File "/home/omkar/git/ctxdoing/backend/ve/lib/python3.6/site-packages/flask/app.py", line 1718, in handle_user_exception
    reraise(exc_type, exc_value, tb)
  File "/home/omkar/git/ctxdoing/backend/ve/lib/python3.6/site-packages/flask/_compat.py", line 35, in reraise
    raise value
  File "/home/omkar/git/ctxdoing/backend/ve/lib/python3.6/site-packages/flask/app.py", line 1813, in full_dispatch_request
    rv = self.dispatch_request()
  File "/home/omkar/git/ctxdoing/backend/ve/lib/python3.6/site-packages/flask/app.py", line 1799, in dispatch_request
    return self.view_functions[rule.endpoint](**req.view_args)
  File "/home/omkar/git/ctxdoing/backend/rest_api_server/asup_analysis_apis.py", line 241, in analyze_replication_contexts
    final_data_structure=dd.get_replication_analysis(selected_replication_contexts,app)
  File "/home/omkar/git/ctxdoing/backend/rest_api_server/dellemc/datadomain.py", line 758, in get_replication_analysis
    returned_graph=graph.plot_context(list_ctx_usage_time,os.path.join(save_name_path,save_name))
  File "/home/omkar/git/ctxdoing/backend/rest_api_server/dellemc/replicationcontextplot.py", line 86, in plot_context
    fig1, ax1 = plt.subplots()
  File "/home/omkar/git/ctxdoing/backend/ve/lib/python3.6/site-packages/matplotlib/pyplot.py", line 1217, in subplots
    fig = figure(**fig_kw)
  File "/home/omkar/git/ctxdoing/backend/ve/lib/python3.6/site-packages/matplotlib/pyplot.py", line 525, in figure
    **kwargs)
  File "/home/omkar/git/ctxdoing/backend/ve/lib/python3.6/site-packages/matplotlib/backend_bases.py", line 3218, in new_figure_manager
    return cls.new_figure_manager_given_figure(num, fig)
  File "/home/omkar/git/ctxdoing/backend/ve/lib/python3.6/site-packages/matplotlib/backends/_backend_tk.py", line 1008, in new_figure_manager_given_figure
    window = Tk.Tk(className="matplotlib")
  File "/usr/lib/python3.6/tkinter/__init__.py", line 2023, in __init__
    self.tk = _tkinter.create(screenName, baseName, className, interactive, wantobjects, useTk, sync, use)
_tkinter.TclError: couldn't connect to display "localhost:10.0"
INFO     Reset uploaded ASUP files
INFO     Reset uploaded ASUP files
INFO     [asup_file_input_method=FILE_UPLOAD] ASUP file saved locally as: /home/omkar/git/ctxdoing/backend/autosupportturco
INFO     [asup_file_input_method=FILE_UPLOAD] ASUP file saved locally as: /home/omkar/git/ctxdoing/backend/autosupportturco
INFO     Selected ASUP files for analysis: [{'filePath': 'autosupportturco', 'generatedDate': 'Thu Feb 14 2019 06:12:51'}]
WARNING  The name of the autosupport file for calculating lrepl_client_time_stats:b'autosupportturco'
WARNING  The name of the autosupport file for calculating lrepl_client_time_stats:b'autosupportturco'
ERROR    Exception on /api/asup/analysis/replication_contexts/time_spent [GET]
Traceback (most recent call last):
  File "/home/omkar/git/ctxdoing/backend/ve/lib/python3.6/site-packages/flask/app.py", line 2292, in wsgi_app
    response = self.full_dispatch_request()
  File "/home/omkar/git/ctxdoing/backend/ve/lib/python3.6/site-packages/flask/app.py", line 1815, in full_dispatch_request
    rv = self.handle_user_exception(e)
  File "/home/omkar/git/ctxdoing/backend/ve/lib/python3.6/site-packages/flask_cors/extension.py", line 161, in wrapped_function
    return cors_after_request(app.make_response(f(*args, **kwargs)))
  File "/home/omkar/git/ctxdoing/backend/ve/lib/python3.6/site-packages/flask/app.py", line 1718, in handle_user_exception
    reraise(exc_type, exc_value, tb)
  File "/home/omkar/git/ctxdoing/backend/ve/lib/python3.6/site-packages/flask/_compat.py", line 35, in reraise
    raise value
  File "/home/omkar/git/ctxdoing/backend/ve/lib/python3.6/site-packages/flask/app.py", line 1813, in full_dispatch_request
    rv = self.dispatch_request()
  File "/home/omkar/git/ctxdoing/backend/ve/lib/python3.6/site-packages/flask/app.py", line 1799, in dispatch_request
    return self.view_functions[rule.endpoint](**req.view_args)
  File "/home/omkar/git/ctxdoing/backend/rest_api_server/asup_analysis_apis.py", line 241, in analyze_replication_contexts
    final_data_structure=dd.get_replication_analysis(selected_replication_contexts,app)
  File "/home/omkar/git/ctxdoing/backend/rest_api_server/dellemc/datadomain.py", line 758, in get_replication_analysis
    returned_graph=graph.plot_context(list_ctx_usage_time,os.path.join(save_name_path,save_name))
  File "/home/omkar/git/ctxdoing/backend/rest_api_server/dellemc/replicationcontextplot.py", line 86, in plot_context
    fig1, ax1 = plt.subplots()
  File "/home/omkar/git/ctxdoing/backend/ve/lib/python3.6/site-packages/matplotlib/pyplot.py", line 1217, in subplots
    fig = figure(**fig_kw)
  File "/home/omkar/git/ctxdoing/backend/ve/lib/python3.6/site-packages/matplotlib/pyplot.py", line 525, in figure
    **kwargs)
  File "/home/omkar/git/ctxdoing/backend/ve/lib/python3.6/site-packages/matplotlib/backend_bases.py", line 3218, in new_figure_manager
    return cls.new_figure_manager_given_figure(num, fig)
  File "/home/omkar/git/ctxdoing/backend/ve/lib/python3.6/site-packages/matplotlib/backends/_backend_tk.py", line 1008, in new_figure_manager_given_figure
    window = Tk.Tk(className="matplotlib")
  File "/usr/lib/python3.6/tkinter/__init__.py", line 2023, in __init__
    self.tk = _tkinter.create(screenName, baseName, className, interactive, wantobjects, useTk, sync, use)
_tkinter.TclError: couldn't connect to display "localhost:10.0"
INFO     Reset uploaded ASUP files
INFO     [asup_file_input_method=FILE_UPLOAD] ASUP file saved locally as: /home/omkar/git/ctxdoing/backend/autosupport
INFO     Selected ASUP files for analysis: [{'filePath': 'autosupport', 'generatedDate': 'Sat Jan 19 2019 06:26:57'}]
WARNING  The name of the autosupport file for calculating lrepl_client_time_stats:b'autosupport'
WARNING  The name of the autosupport file for calculating lrepl_client_time_stats:b'autosupport'
ERROR    Exception on /api/asup/analysis/replication_contexts/time_spent [GET]
Traceback (most recent call last):
  File "/home/omkar/git/ctxdoing/backend/ve/lib/python3.6/site-packages/flask/app.py", line 2292, in wsgi_app
    response = self.full_dispatch_request()
  File "/home/omkar/git/ctxdoing/backend/ve/lib/python3.6/site-packages/flask/app.py", line 1815, in full_dispatch_request
    rv = self.handle_user_exception(e)
  File "/home/omkar/git/ctxdoing/backend/ve/lib/python3.6/site-packages/flask_cors/extension.py", line 161, in wrapped_function
    return cors_after_request(app.make_response(f(*args, **kwargs)))
  File "/home/omkar/git/ctxdoing/backend/ve/lib/python3.6/site-packages/flask/app.py", line 1718, in handle_user_exception
    reraise(exc_type, exc_value, tb)
  File "/home/omkar/git/ctxdoing/backend/ve/lib/python3.6/site-packages/flask/_compat.py", line 35, in reraise
    raise value
  File "/home/omkar/git/ctxdoing/backend/ve/lib/python3.6/site-packages/flask/app.py", line 1813, in full_dispatch_request
    rv = self.dispatch_request()
  File "/home/omkar/git/ctxdoing/backend/ve/lib/python3.6/site-packages/flask/app.py", line 1799, in dispatch_request
    return self.view_functions[rule.endpoint](**req.view_args)
  File "/home/omkar/git/ctxdoing/backend/rest_api_server/asup_analysis_apis.py", line 241, in analyze_replication_contexts
    final_data_structure=dd.get_replication_analysis(selected_replication_contexts,app)
  File "/home/omkar/git/ctxdoing/backend/rest_api_server/dellemc/datadomain.py", line 758, in get_replication_analysis
    returned_graph=graph.plot_context(list_ctx_usage_time,os.path.join(save_name_path,save_name))
  File "/home/omkar/git/ctxdoing/backend/rest_api_server/dellemc/replicationcontextplot.py", line 86, in plot_context
    fig1, ax1 = plt.subplots()
  File "/home/omkar/git/ctxdoing/backend/ve/lib/python3.6/site-packages/matplotlib/pyplot.py", line 1217, in subplots
    fig = figure(**fig_kw)
  File "/home/omkar/git/ctxdoing/backend/ve/lib/python3.6/site-packages/matplotlib/pyplot.py", line 525, in figure
    **kwargs)
  File "/home/omkar/git/ctxdoing/backend/ve/lib/python3.6/site-packages/matplotlib/backend_bases.py", line 3218, in new_figure_manager
    return cls.new_figure_manager_given_figure(num, fig)
  File "/home/omkar/git/ctxdoing/backend/ve/lib/python3.6/site-packages/matplotlib/backends/_backend_tk.py", line 1008, in new_figure_manager_given_figure
    window = Tk.Tk(className="matplotlib")
  File "/usr/lib/python3.6/tkinter/__init__.py", line 2023, in __init__
    self.tk = _tkinter.create(screenName, baseName, className, interactive, wantobjects, useTk, sync, use)
_tkinter.TclError: couldn't connect to display "localhost:10.0"
WARNING  The name of the autosupport file for calculating lrepl_client_time_stats:b'autosupport'
[2019-04-12 23:44:27 -0400] [14613] [INFO] Starting gunicorn 19.9.0
[2019-04-12 23:44:27 -0400] [14613] [INFO] Listening at: http://127.0.0.1:8000 (14613)
[2019-04-12 23:44:27 -0400] [14613] [INFO] Using worker: sync
[2019-04-12 23:44:27 -0400] [14616] [INFO] Booting worker with pid: 14616
INFO     
ctxdoing
============================
v1.0.1 beta released on 13-Apr-2019
============================
OS: Linux-4.15.0-47-generic-x86_64-with-Ubuntu-18.04-bionic
Python: 3.6.7 (default, Oct 22 2018, 11:32:17) 
[GCC 8.2.0]
System: omkar on ubuntu1604/10.141.56.42
Working directory: /home/omkar/git/ctxdoing/backend
Commandline: /home/omkar/git/ctxdoing/ve/bin/gunicorn wsgi
============================
Log file: /home/omkar/git/ctxdoing/backend/ctxdoing.log
============================
    
INFO     [AUTO_EXPIRE] Start scheduler at an interval of 15 minutes
INFO     [AUTO_EXPIRE] Check for expired sessions every 15 minutes
INFO     [AUTO_EXPIRE] Begin auto-expiring 0 DD engine objects...
INFO     Creating an instance of DellUser for omkar.ekbote@dell.com
INFO     Logged in as user: DellUser <omkar.ekbote@dell.com>
INFO     Reset uploaded ASUP files
INFO     [asup_file_input_method=FILE_UPLOAD] ASUP file saved locally as: /tmp/tmpn804922u/omkar.ekbote@dell.com/autosupport.1
INFO     REST API returns version: {'version': 'RCA v1.0.1 beta released on 13-Apr-2019'}
INFO     Logged out user: DellUser <omkar.ekbote@dell.com>
INFO     Creating an instance of DellUser for omkar.ekbote@dell.com
INFO     Logged in as user: DellUser <omkar.ekbote@dell.com>
INFO     Reset uploaded ASUP files
INFO     [asup_file_input_method=FILE_UPLOAD] ASUP file saved locally as: /tmp/tmpn804922u/omkar.ekbote@dell.com/autosupport.1
INFO     Logged out user: <flask_login.mixins.AnonymousUserMixin object at 0x7fec76645748>
INFO     Creating an instance of DellUser for omkar.ekbote@dell.com
INFO     Logged in as user: DellUser <omkar.ekbote@dell.com>
INFO     Reset uploaded ASUP files
INFO     [asup_file_input_method=FILE_UPLOAD] ASUP file saved locally as: /tmp/tmpn804922u/omkar.ekbote@dell.com/autosupport.1
INFO     Creating an instance of DellUser for omkar.ekbote@dell.com
INFO     Logged in as user: DellUser <omkar.ekbote@dell.com>
INFO     Reset uploaded ASUP files
INFO     [asup_file_input_method=FILE_UPLOAD] ASUP file saved locally as: /tmp/tmpn804922u/omkar.ekbote@dell.com/autosupport
INFO     Logged out user: DellUser <omkar.ekbote@dell.com>
INFO     Creating an instance of DellUser for omkar.ekbote@dell.com
INFO     Logged in as user: DellUser <omkar.ekbote@dell.com>
INFO     Creating an instance of DellUser for omkar.ekbote@dell.com
INFO     Logged in as user: DellUser <omkar.ekbote@dell.com>
INFO     Reset uploaded ASUP files
INFO     [asup_file_input_method=FILE_UPLOAD] ASUP file saved locally as: /tmp/tmpn804922u/omkar.ekbote@dell.com/autosupport
INFO     [AUTO_EXPIRE] Check for expired sessions every 15 minutes
INFO     [AUTO_EXPIRE] Begin auto-expiring 0 DD engine objects...
INFO     Creating an instance of DellUser for omkar.ekbote@dell.com
INFO     Logged in as user: DellUser <omkar.ekbote@dell.com>
INFO     Reset uploaded ASUP files
INFO     [asup_file_input_method=FILE_UPLOAD] ASUP file saved locally as: /tmp/tmpn804922u/omkar.ekbote@dell.com/autosupport
INFO     [AUTO_EXPIRE] Check for expired sessions every 15 minutes
INFO     [AUTO_EXPIRE] Begin auto-expiring 0 DD engine objects...
INFO     REST API returns version: {'version': 'RCA v1.0.1 beta released on 13-Apr-2019'}
INFO     REST API returns version: {'version': 'RCA v1.0.1 beta released on 13-Apr-2019'}
[2019-04-13 00:17:11 -0400] [14613] [INFO] Handling signal: term
[2019-04-13 00:17:11 -0400] [14613] [INFO] Shutting down: Master
[2019-04-13 00:57:41 -0400] [15718] [INFO] Starting gunicorn 19.9.0
[2019-04-13 00:57:41 -0400] [15718] [INFO] Listening at: http://127.0.0.1:8000 (15718)
[2019-04-13 00:57:41 -0400] [15718] [INFO] Using worker: sync
[2019-04-13 00:57:41 -0400] [15721] [INFO] Booting worker with pid: 15721
INFO     
ctxdoing
============================
v1.0.1 beta released on 13-Apr-2019
============================
OS: Linux-4.15.0-47-generic-x86_64-with-Ubuntu-18.04-bionic
Python: 3.6.7 (default, Oct 22 2018, 11:32:17) 
[GCC 8.2.0]
System: omkar on ubuntu1604/10.141.56.42
Working directory: /home/omkar/git/ctxdoing/backend
Commandline: /home/omkar/git/ctxdoing/ve/bin/gunicorn wsgi
============================
Log file: /home/omkar/git/ctxdoing/backend/ctxdoing.log
============================
    
INFO     [AUTO_EXPIRE] Start scheduler at an interval of 15 minutes
INFO     [AUTO_EXPIRE] Check for expired sessions every 15 minutes
INFO     [AUTO_EXPIRE] Begin auto-expiring 0 DD engine objects...
INFO     REST API returns version: {'version': 'RCA v1.0.1 beta released on 13-Apr-2019'}
INFO     Creating an instance of DellUser for omkar.ekbote@dell.com
INFO     Logged in as user: DellUser <omkar.ekbote@dell.com>
INFO     Reset uploaded ASUP files
INFO     [asup_file_input_method=FILE_UPLOAD] ASUP file saved locally as: /tmp/tmpquvvwg7y/omkar.ekbote@dell.com/autosupport
INFO     [asup_file_input_method=FILE_UPLOAD] ASUP file saved locally as: /tmp/tmpquvvwg7y/omkar.ekbote@dell.com/autosupport.1
INFO     Creating an instance of DellUser for omkar.ekbote@dell.com
INFO     Logged in as user: DellUser <omkar.ekbote@dell.com>
INFO     Reset uploaded ASUP files
INFO     [asup_file_input_method=FILE_UPLOAD] ASUP file saved locally as: /tmp/tmpquvvwg7y/omkar.ekbote@dell.com/autosupport
INFO     [asup_file_input_method=FILE_UPLOAD] ASUP file saved locally as: /tmp/tmpquvvwg7y/omkar.ekbote@dell.com/autosupport.1
INFO     [AUTO_EXPIRE] Check for expired sessions every 15 minutes
INFO     [AUTO_EXPIRE] Begin auto-expiring 0 DD engine objects...
INFO     [AUTO_EXPIRE] Check for expired sessions every 15 minutes
INFO     [AUTO_EXPIRE] Begin auto-expiring 0 DD engine objects...
[2019-04-13 01:33:55 -0400] [15718] [INFO] Handling signal: term
[2019-04-13 01:33:55 -0400] [15718] [INFO] Shutting down: Master
[2019-04-13 01:37:05 -0400] [15865] [INFO] Starting gunicorn 19.9.0
[2019-04-13 01:37:05 -0400] [15865] [INFO] Listening at: http://127.0.0.1:8000 (15865)
[2019-04-13 01:37:05 -0400] [15865] [INFO] Using worker: sync
[2019-04-13 01:37:05 -0400] [15869] [INFO] Booting worker with pid: 15869
INFO     
ctxdoing
============================
v1.0.1 beta released on 13-Apr-2019
============================
OS: Linux-4.15.0-47-generic-x86_64-with-Ubuntu-18.04-bionic
Python: 3.6.7 (default, Oct 22 2018, 11:32:17) 
[GCC 8.2.0]
System: omkar on ubuntu1604/10.141.56.42
Working directory: /home/omkar/git/ctxdoing/backend
Commandline: /home/omkar/git/ctxdoing/ve/bin/gunicorn wsgi
============================
Log file: /home/omkar/git/ctxdoing/backend/ctxdoing.log
============================
    
INFO     [AUTO_EXPIRE] Start scheduler at an interval of 15 minutes
INFO     [AUTO_EXPIRE] Check for expired sessions every 15 minutes
INFO     [AUTO_EXPIRE] Begin auto-expiring 0 DD engine objects...
INFO     Creating an instance of DellUser for omkar.ekbote@dell.com
INFO     Logged in as user: DellUser <omkar.ekbote@dell.com>
INFO     Reset uploaded ASUP files
INFO     [asup_file_input_method=FILE_UPLOAD] ASUP file saved locally as: /tmp/tmpx6_fv7d2/omkar.ekbote@dell.com/autosupport
INFO     [asup_file_input_method=FILE_UPLOAD] ASUP file saved locally as: /tmp/tmpx6_fv7d2/omkar.ekbote@dell.com/autosupport.1
[2019-04-13 01:39:39 -0400] [15865] [INFO] Handling signal: term
[2019-04-13 01:39:39 -0400] [15865] [INFO] Shutting down: Master
[2019-04-13 01:39:43 -0400] [15988] [INFO] Starting gunicorn 19.9.0
[2019-04-13 01:39:43 -0400] [15988] [INFO] Listening at: http://127.0.0.1:8000 (15988)
[2019-04-13 01:39:43 -0400] [15988] [INFO] Using worker: sync
[2019-04-13 01:39:43 -0400] [15991] [INFO] Booting worker with pid: 15991
INFO     
ctxdoing
============================
v1.0.1 beta released on 13-Apr-2019
============================
OS: Linux-4.15.0-47-generic-x86_64-with-Ubuntu-18.04-bionic
Python: 3.6.7 (default, Oct 22 2018, 11:32:17) 
[GCC 8.2.0]
System: omkar on ubuntu1604/10.141.56.42
Working directory: /home/omkar/git/ctxdoing/backend
Commandline: /home/omkar/git/ctxdoing/ve/bin/gunicorn wsgi
============================
Log file: /home/omkar/git/ctxdoing/backend/ctxdoing.log
============================
    
INFO     [AUTO_EXPIRE] Start scheduler at an interval of 15 minutes
INFO     [AUTO_EXPIRE] Check for expired sessions every 15 minutes
INFO     [AUTO_EXPIRE] Begin auto-expiring 0 DD engine objects...
INFO     Creating an instance of DellUser for omkar.ekbote@dell.com
INFO     Logged in as user: DellUser <omkar.ekbote@dell.com>
INFO     Reset uploaded ASUP files
INFO     Deleting all ASUP files at: /tmp/tmpaiun81fk/omkar.ekbote@dell.com
INFO     [asup_file_input_method=FILE_UPLOAD] ASUP file saved locally as: /tmp/tmpaiun81fk/omkar.ekbote@dell.com/autosupport
INFO     [asup_file_input_method=FILE_UPLOAD] ASUP file saved locally as: /tmp/tmpaiun81fk/omkar.ekbote@dell.com/autosupport.1
INFO     ASUP files uploaded for current session: ['autosupport', 'autosupport.1']
INFO     ASUP files uploaded for current session: ['autosupport', 'autosupport.1']
ERROR    Exception on /api/asup/metadata_list/ [GET]
Traceback (most recent call last):
  File "/home/omkar/git/ctxdoing/ve/lib/python3.6/site-packages/flask/app.py", line 2292, in wsgi_app
    response = self.full_dispatch_request()
  File "/home/omkar/git/ctxdoing/ve/lib/python3.6/site-packages/flask/app.py", line 1815, in full_dispatch_request
    rv = self.handle_user_exception(e)
  File "/home/omkar/git/ctxdoing/ve/lib/python3.6/site-packages/flask_cors/extension.py", line 161, in wrapped_function
    return cors_after_request(app.make_response(f(*args, **kwargs)))
  File "/home/omkar/git/ctxdoing/ve/lib/python3.6/site-packages/flask/app.py", line 1718, in handle_user_exception
    reraise(exc_type, exc_value, tb)
  File "/home/omkar/git/ctxdoing/ve/lib/python3.6/site-packages/flask/_compat.py", line 35, in reraise
    raise value
  File "/home/omkar/git/ctxdoing/ve/lib/python3.6/site-packages/flask/app.py", line 1813, in full_dispatch_request
    rv = self.dispatch_request()
  File "/home/omkar/git/ctxdoing/ve/lib/python3.6/site-packages/flask/app.py", line 1799, in dispatch_request
    return self.view_functions[rule.endpoint](**req.view_args)
  File "/home/omkar/git/ctxdoing/ve/lib/python3.6/site-packages/flask_classy.py", line 200, in proxy
    response = view(**request.view_args)
  File "/home/omkar/git/ctxdoing/ve/lib/python3.6/site-packages/flask_login/utils.py", line 261, in decorated_view
    return func(*args, **kwargs)
  File "/home/omkar/git/ctxdoing/backend/rest_api_server/asup_analysis_apis.py", line 230, in metadata_list
    dd_obj.use_asup_file(asup_file_save_path_escaped)
  File "/home/omkar/git/ctxdoing/backend/rest_api_server/dellemc/datadomain.py", line 88, in use_asup_file
    with open (self.current_autosupport_name,'r') as autosupport_fd:
FileNotFoundError: [Errno 2] No such file or directory: b'autosupport.1'
[2019-04-13 01:45:06 -0400] [15988] [INFO] Handling signal: term
[2019-04-13 01:45:06 -0400] [15988] [INFO] Shutting down: Master
